Workbook

Sheet Dashboard
A1: DASHBOARD – BC VIỆT NAM TÀI CHÍNH
A3: TỔNG QUAN TÀI CHÍNH THÁNG HIỆN TẠI
A4: Tổng doanh thu tháng | B4: ='P&L 12T'!B12 -> 321.5 | C4: Trạng thái
A5: Tổng chi phí nhân sự | B5: ='P&L 12T'!B22 -> 301.875
A6: Tổng chi phí cố định | B6: ='P&L 12T'!B34 -> 71
A7: Lợi nhuận gộp | B7: ='P&L 12T'!B24 -> 19.625
A8: Biên LN gộp | B8: ='P&L 12T'!B25 -> 0.061041991
A9: EBITDA | B9: ='P&L 12T'!B36 -> -51.375 | C9: =IF(B9>0,"✔ Tốt",IF(B9>-10,"◐ Cần cải thiện","✘ Thấp")) -> ✘ Thấp
A10: EBITDA Margin | B10: ='P&L 12T'!B37 -> -0.15979782 | C10: =IF(B10>0.15,"✔ Tốt",IF(B10>0,"◐ TB","✘ Lỗ")) -> ✘ Lỗ
A11: Số KH hiện tại | B11: ='Đầu Vào'!$F$12 -> 16
A12: Số KH hòa vốn | B12: ='Hòa Vốn'!B11 -> 58
A13: Tháng hòa vốn dự kiến | B13: ='Hòa Vốn'!B17 -> 28
A15: DOANH THU & MARGIN THEO GÓI
A16: Gói dịch vụ | B16: DT/tháng | C16: Biên LN gộp | D16: Số KH | E16: Trạng thái
A17: G1 – BC Performance Ads™ | B17: ='P&L 12T'!B5 -> 109 | C17: =IF('P&L 12T'!B5=0,0,('P&L 12T'!B5-'P&L 12T'!B15)/'P&L 12T'!B5) -> 0.26146789 | D17: ='Đầu Vào'!F5 -> 6 | E17: =IF(C17>0.4,"✔ Tốt",IF(C17>0.2,"◐ TB","✘ Cần cải thiện")) -> ◐ TB
A18: G2 – BC SEO & Content™ | B18: ='P&L 12T'!B6 -> 43 | C18: =IF('P&L 12T'!B6=0,0,('P&L 12T'!B6-'P&L 12T'!B16)/'P&L 12T'!B6) -> 0.25116279 | D18: ='Đầu Vào'!F6 -> 3 | E18: =IF(C18>0.4,"✔ Tốt",IF(C18>0.2,"◐ TB","✘ Cần cải thiện")) -> ◐ TB
A19: G3 – BC Social Media™ | B19: ='P&L 12T'!B7 -> 34.5 | C19: =IF('P&L 12T'!B7=0,0,('P&L 12T'!B7-'P&L 12T'!B17)/'P&L 12T'!B7) -> -0.21666667 | D19: ='Đầu Vào'!F7 -> 3 | E19: =IF(C19>0.4,"✔ Tốt",IF(C19>0.2,"◐ TB","✘ Cần cải thiện")) -> ✘ Cần cải thiện
A20: G4 – BC TikTok & Social Commerce™ | B20: ='P&L 12T'!B8 -> 35 | C20: =IF('P&L 12T'!B8=0,0,('P&L 12T'!B8-'P&L 12T'!B18)/'P&L 12T'!B8) -> -0.21571429 | D20: ='Đầu Vào'!F8 -> 2 | E20: =IF(C20>0.4,"✔ Tốt",IF(C20>0.2,"◐ TB","✘ Cần cải thiện")) -> ✘ Cần cải thiện
A21: G5 – BC Digital Brand™ | B21: ='P&L 12T'!B9 -> 20 | C21: =IF('P&L 12T'!B9=0,0,('P&L 12T'!B9-'P&L 12T'!B19)/'P&L 12T'!B9) -> 0.1375 | D21: ='Đầu Vào'!F9 -> 1 | E21: =IF(C21>0.4,"✔ Tốt",IF(C21>0.2,"◐ TB","✘ Cần cải thiện")) -> ✘ Cần cải thiện
A22: G6 – BC Marketing Automation™ | B22: ='P&L 12T'!B10 -> 0 | C22: =IF('P&L 12T'!B10=0,0,('P&L 12T'!B10-'P&L 12T'!B20)/'P&L 12T'!B10) -> 0 | D22: ='Đầu Vào'!F10 -> 0 | E22: =IF(C22>0.4,"✔ Tốt",IF(C22>0.2,"◐ TB","✘ Cần cải thiện")) -> ✘ Cần cải thiện
A23: G7 – BC Total Growth™ | B23: ='P&L 12T'!B11 -> 80 | C23: =IF('P&L 12T'!B11=0,0,('P&L 12T'!B11-'P&L 12T'!B21)/'P&L 12T'!B11) -> -0.0925 | D23: ='Đầu Vào'!F11 -> 1 | E23: =IF(C23>0.4,"✔ Tốt",IF(C23>0.2,"◐ TB","✘ Cần cải thiện")) -> ✘ Cần cải thiện
A25: DỰ BÁO NĂM (12 THÁNG)
A26: Tổng DT năm | B26: ='P&L 12T'!N12 -> 5117.3562
A27: Tổng LN gộp năm | B27: ='P&L 12T'!N24 -> 312.37361
A28: Tổng EBITDA năm | B28: ='P&L 12T'!N36 -> -539.62639
A29: EBITDA Margin năm | B29: ='P&L 12T'!N37 -> -0.10545023
A30: Số KH cuối năm | B30: ='P&L 12T'!M39 -> 27

Sheet Đầu Vào
A1: CẤU HÌNH ĐẦU VÀO – MÔ HÌNH TÀI CHÍNH BC VIỆT NAM
A3: PHẦN A – SỐ KHÁCH HÀNG HIỆN TẠI / KẾ HOẠCH | H3: BẢNG CHI PHÍ NHÂN SỰ/KH (triệu/tháng)
A4: Gói dịch vụ | B4: Mô hình NS | C4: Cơ Bản (CB) | D4: Tiêu Chuẩn (TC) | E4: Cao Cấp (CC) | F4: Tổng | H4: MÔ HÌNH 1 (Senior PM + Junior) | M4: MÔ HÌNH 2 (All Junior) — 0 = không khả dụng
A5: G1 – BC Performance Ads™ | B5: Mô hình 1 | C5: 3 | D5: 2 | E5: 1 | F5: =SUM(C5:E5) -> 6 | H5: Gói | I5: CB | J5: TC | K5: CC | M5: Gói | N5: CB | O5: TC | P5: CC
A6: G2 – BC SEO & Content™ | B6: Mô hình 1 | C6: 2 | D6: 1 | E6: 0 | F6: =SUM(C6:E6) -> 3 | H6: G1 | I6: 6 | J6: 12.5 | K6: 27 | M6: G1 | N6: 4 | O6: 9 | P6: 18.5
A7: G3 – BC Social Media™ | B7: Mô hình 1 | C7: 2 | D7: 1 | E7: 0 | F7: =SUM(C7:E7) -> 3 | H7: G2 | I7: 6.5 | J7: 15 | K7: 31.5 | M7: G2 | N7: 5 | O7: 11.5 | P7: 23
A8: G4 – BC TikTok & Social Commerce™ | B8: Mô hình 1 | C8: 1 | D8: 1 | E8: 0 | F8: =SUM(C8:E8) -> 2 | H8: G3 | I8: 9.5 | J8: 17.5 | K8: 36 | M8: G3 | N8: 6 | O8: 12.5 | P8: 29.5
A9: G5 – BC Digital Brand™ | B9: Mô hình 1 | C9: 1 | D9: 0 | E9: 0 | F9: =SUM(C9:E9) -> 1 | H9: G4 | I9: 12 | J9: 25 | K9: 52.5 | M9: G4 | N9: 8.5 | O9: 0 | P9: 0
A10: G6 – BC Marketing Automation™ | B10: Mô hình 1 | C10: 0 | D10: 0 | E10: 0 | F10: =SUM(C10:E10) -> 0 | H10: G5 | I10: 15 | J10: 34 | K10: 67.5 | M10: G5 | N10: 9.5 | O10: 23 | P10: 0
A11: G7 – BC Total Growth™ | B11: Mô hình 1 | C11: 0 | D11: 1 | E11: 0 | F11: =SUM(C11:E11) -> 1 | H11: G6 | I11: 23.5 | J11: 38.5 | K11: 62 | M11: G6 | N11: 0 | O11: 0 | P11: 0
A12: TỔNG KHÁCH HÀNG | C12: =SUM(C5:C11) -> 9 | D12: =SUM(D5:D11) -> 6 | E12: =SUM(E5:E11) -> 1 | F12: =SUM(F5:F11) -> 16 | H12: G7 | I12: 46.5 | J12: 76 | K12: 145 | M12: G7 | N12: 38.5 | O12: 0 | P12: 0
A14: PHẦN B – GIÁ DỊCH VỤ TRUNG BÌNH (triệu VND/tháng)
A15: Gói dịch vụ | C15: Cơ Bản | D15: Tiêu Chuẩn | E15: Cao Cấp
A16: G1 – BC Performance Ads™ | C16: 10.5 | D16: 20 | E16: 37.5
A17: G2 – BC SEO & Content™ | C17: 10 | D17: 23 | E17: 45
A18: G3 – BC Social Media™ | C18: 8 | D18: 18.5 | E18: 32.5
A19: G4 – BC TikTok & Social Commerce™ | C19: 10 | D19: 25 | E19: 50
A20: G5 – BC Digital Brand™ | C20: 20 | D20: 47.5 | E20: 95
A21: G6 – BC Marketing Automation™ | C21: 6.5 | D21: 16 | E21: 35
A22: G7 – BC Total Growth™ | C22: 45 | D22: 80 | E22: 160
A23: G6 – Phí Setup (một lần) | C23: 12.5 | D23: 27.5 | E23: 65
A25: PHẦN C – CHI PHÍ NHÂN SỰ
A26: Lương tham chiếu (triệu/tháng gross)
A27: Vị trí | B27: Lương gross
A28: Junior Specialist (0-2 năm) | B28: 10.5
A29: Mid-level (2-4 năm) | B29: 16.5
A30: Senior Specialist (4+ năm) | B30: 25
A31: Senior PM / Account Manager | B31: 33
A32: Account Director | B32: 52.5
A34: Hệ số overhead (BHXH, thưởng...) | B34: 1.15
A35: Số nhân viên hiện tại (headcount) | B35: 5
A37: PHẦN D – CHI PHÍ CỐ ĐỊNH HÀNG THÁNG (triệu VND)
A38: Hạng mục | B38: Số tiền
A39: Thuê văn phòng | B39: 15
A40: Lương quản lý (BGĐ) | B40: 30
A41: Chi phí công cụ SaaS | B41: 13
A42: Chi phí khác (điện, internet...) | B42: 5
A43: Khấu hao thiết bị | B43: 3
A44: Marketing cho BC | B44: 5
A45: TỔNG CHI PHÍ CỐ ĐỊNH | B45: =SUM(B39:B44) -> 71
...

Sheet UE G1-G4
A1: UNIT ECONOMICS – GÓI 1 ĐẾN 4
A3: G1 – BC Performance Ads™
A4: Chỉ số | B4: Cơ Bản (CB) | C4: Tiêu Chuẩn (TC) | D4: Cao Cấp (CC)
A5: Doanh thu/KH/tháng | B5: ='Đầu Vào'!C16 -> 10.5 | C5: ='Đầu Vào'!D16 -> 20 | D5: ='Đầu Vào'!E16 -> 37.5
A6: Chi phí NS/KH/tháng | B6: =IF('Đầu Vào'!$B$5="Mô hình 1",'Đầu Vào'!$I$6,'Đầu Vào'!$N$6)*'Đầu Vào'!$B$34 -> 6.9 | C6: =IF('Đầu Vào'!$B$5="Mô hình 1",'Đầu Vào'!$J$6,'Đầu Vào'!$O$6)*'Đầu Vào'!$B$34 -> 14.375 | D6: =IF('Đầu Vào'!$B$5="Mô hình 1",'Đầu Vào'!$K$6,'Đầu Vào'!$P$6)*'Đầu Vào'!$B$34 -> 31.05
A7: Chi phí tools/KH | B7: =IFERROR('Đầu Vào'!$B$41/'Đầu Vào'!$F$12,0) -> 0.8125 | C7: =IFERROR('Đầu Vào'!$B$41/'Đầu Vào'!$F$12,0) -> 0.8125 | D7: =IFERROR('Đầu Vào'!$B$41/'Đầu Vào'!$F$12,0) -> 0.8125
A8: Lợi nhuận gộp/KH | B8: =B5-B6-B7 -> 2.7875 | C8: =C5-C6-C7 -> 4.8125 | D8: =D5-D6-D7 -> 5.6375
A9: Biên LN gộp (%) | B9: =IF(B5=0,0,B8/B5) -> 0.26547619 | C9: =IF(C5=0,0,C8/C5) -> 0.240625 | D9: =IF(D5=0,0,D8/D5) -> 0.15033333
A10: Chi phí overhead/KH | B10: =IFERROR(('Đầu Vào'!$B$45-'Đầu Vào'!$B$41)/'Đầu Vào'!$F$12,0) -> 3.625 | C10: =IFERROR(('Đầu Vào'!$B$45-'Đầu Vào'!$B$41)/'Đầu Vào'!$F$12,0) -> 3.625 | D10: =IFERROR(('Đầu Vào'!$B$45-'Đầu Vào'!$B$41)/'Đầu Vào'!$F$12,0) -> 3.625
A11: Lợi nhuận ròng/KH | B11: =B8-B10 -> -0.8375 | C11: =C8-C10 -> 1.1875 | D11: =D8-D10 -> 2.0125
A12: Biên LN ròng (%) | B12: =IF(B5=0,0,B11/B5) -> -0.079761905 | C12: =IF(C5=0,0,C11/C5) -> 0.059375 | D12: =IF(D5=0,0,D11/D5) -> 0.053666667
A13: Số KH hòa vốn | B13: =IFERROR(ROUNDUP('Đầu Vào'!$B$45/IF(B5-B6<=0,0.001,B5-B6),0),0) -> 20 | C13: =IFERROR(ROUNDUP('Đầu Vào'!$B$45/IF(C5-C6<=0,0.001,C5-C6),0),0) -> 13 | D13: =IFERROR(ROUNDUP('Đầu Vào'!$B$45/IF(D5-D6<=0,0.001,D5-D6),0),0) -> 12
A15: G2 – BC SEO & Content™
A16: Chỉ số | B16: Cơ Bản (CB) | C16: Tiêu Chuẩn (TC) | D16: Cao Cấp (CC)
A17: Doanh thu/KH/tháng | B17: ='Đầu Vào'!C17 -> 10 | C17: ='Đầu Vào'!D17 -> 23 | D17: ='Đầu Vào'!E17 -> 45
A18: Chi phí NS/KH/tháng | B18: =IF('Đầu Vào'!$B$6="Mô hình 1",'Đầu Vào'!$I$7,'Đầu Vào'!$N$7)*'Đầu Vào'!$B$34 -> 7.475 | C18: =IF('Đầu Vào'!$B$6="Mô hình 1",'Đầu Vào'!$J$7,'Đầu Vào'!$O$7)*'Đầu Vào'!$B$34 -> 17.25 | D18: =IF('Đầu Vào'!$B$6="Mô hình 1",'Đầu Vào'!$K$7,'Đầu Vào'!$P$7)*'Đầu Vào'!$B$34 -> 36.225
A19: Chi phí tools/KH | B19: =IFERROR('Đầu Vào'!$B$41/'Đầu Vào'!$F$12,0) -> 0.8125 | C19: =IFERROR('Đầu Vào'!$B$41/'Đầu Vào'!$F$12,0) -> 0.8125 | D19: =IFERROR('Đầu Vào'!$B$41/'Đầu Vào'!$F$12,0) -> 0.8125
A20: Lợi nhuận gộp/KH | B20: =B17-B18-B19 -> 1.7125 | C20: =C17-C18-C19 -> 4.9375 | D20: =D17-D18-D19 -> 7.9625
A21: Biên LN gộp (%) | B21: =IF(B17=0,0,B20/B17) -> 0.17125 | C21: =IF(C17=0,0,C20/C17) -> 0.21467391 | D21: =IF(D17=0,0,D20/D17) -> 0.17694444
A22: Chi phí overhead/KH | B22: =IFERROR(('Đầu Vào'!$B$45-'Đầu Vào'!$B$41)/'Đầu Vào'!$F$12,0) -> 3.625 | C22: =IFERROR(('Đầu Vào'!$B$45-'Đầu Vào'!$B$41)/'Đầu Vào'!$F$12,0) -> 3.625 | D22: =IFERROR(('Đầu Vào'!$B$45-'Đầu Vào'!$B$41)/'Đầu Vào'!$F$12,0) -> 3.625
A23: Lợi nhuận ròng/KH | B23: =B20-B22 -> -1.9125 | C23: =C20-C22 -> 1.3125 | D23: =D20-D22 -> 4.3375
A24: Biên LN ròng (%) | B24: =IF(B17=0,0,B23/B17) -> -0.19125 | C24: =IF(C17=0,0,C23/C17) -> 0.057065217 | D24: =IF(D17=0,0,D23/D17) -> 0.096388889
A25: Số KH hòa vốn | B25: =IFERROR(ROUNDUP('Đầu Vào'!$B$45/IF(B17-B18<=0,0.001,B17-B18),0),0) -> 29 | C25: =IFERROR(ROUNDUP('Đầu Vào'!$B$45/IF(C17-C18<=0,0.001,C17-C18),0),0) -> 13 | D25: =IFERROR(ROUNDUP('Đầu Vào'!$B$45/IF(D17-D18<=0,0.001,D17-D18),0),0) -> 9
A27: G3 – BC Social Media™
A28: Chỉ số | B28: Cơ Bản (CB) | C28: Tiêu Chuẩn (TC) | D28: Cao Cấp (CC)
A29: Doanh thu/KH/tháng | B29: ='Đầu Vào'!C18 -> 8 | C29: ='Đầu Vào'!D18 -> 18.5 | D29: ='Đầu Vào'!E18 -> 32.5
A30: Chi phí NS/KH/tháng | B30: =IF('Đầu Vào'!$B$7="Mô hình 1",'Đầu Vào'!$I$8,'Đầu Vào'!$N$8)*'Đầu Vào'!$B$34 -> 10.925 | C30: =IF('Đầu Vào'!$B$7="Mô hình 1",'Đầu Vào'!$J$8,'Đầu Vào'!$O$8)*'Đầu Vào'!$B$34 -> 20.125 | D30: =IF('Đầu Vào'!$B$7="Mô hình 1",'Đầu Vào'!$K$8,'Đầu Vào'!$P$8)*'Đầu Vào'!$B$34 -> 41.4
A31: Chi phí tools/KH | B31: =IFERROR('Đầu Vào'!$B$41/'Đầu Vào'!$F$12,0) -> 0.8125 | C31: =IFERROR('Đầu Vào'!$B$41/'Đầu Vào'!$F$12,0) -> 0.8125 | D31: =IFERROR('Đầu Vào'!$B$41/'Đầu Vào'!$F$12,0) -> 0.8125
A32: Lợi nhuận gộp/KH | B32: =B29-B30-B31 -> -3.7375 | C32: =C29-C30-C31 -> -2.4375 | D32: =D29-D30-D31 -> -9.7125
A33: Biên LN gộp (%) | B33: =IF(B29=0,0,B32/B29) -> -0.4671875 | C33: =IF(C29=0,0,C32/C29) -> -0.13175676 | D33: =IF(D29=0,0,D32/D29) -> -0.29884615
A34: Chi phí overhead/KH | B34: =IFERROR(('Đầu Vào'!$B$45-'Đầu Vào'!$B$41)/'Đầu Vào'!$F$12,0) -> 3.625 | C34: =IFERROR(('Đầu Vào'!$B$45-'Đầu Vào'!$B$41)/'Đầu Vào'!$F$12,0) -> 3.625 | D34: =IFERROR(('Đầu Vào'!$B$45-'Đầu Vào'!$B$41)/'Đầu Vào'!$F$12,0) -> 3.625
A35: Lợi nhuận ròng/KH | B35: =B32-B34 -> -7.3625 | C35: =C32-C34 -> -6.0625 | D35: =D32-D34 -> -13.3375
A36: Biên LN ròng (%) | B36: =IF(B29=0,0,B35/B29) -> -0.9203125 | C36: =IF(C29=0,0,C35/C29) -> -0.3277027 | D36: =IF(D29=0,0,D35/D29) -> -0.41038462
A37: Số KH hòa vốn | B37: =IFERROR(ROUNDUP('Đầu Vào'!$B$45/IF(B29-B30<=0,0.001,B29-B30),0),0) -> 71000 | C37: =IFERROR(ROUNDUP('Đầu Vào'!$B$45/IF(C29-C30<=0,0.001,C29-C30),0),0) -> 71000 | D37: =IFERROR(ROUNDUP('Đầu Vào'!$B$45/IF(D29-D30<=0,0.001,D29-D30),0),0) -> 71000
A39: G4 – BC TikTok & Social Commerce™
A40: Chỉ số | B40: Cơ Bản (CB) | C40: Tiêu Chuẩn (TC) | D40: Cao Cấp (CC)
A41: Doanh thu/KH/tháng | B41: ='Đầu Vào'!C19 -> 10 | C41: ='Đầu Vào'!D19 -> 25 | D41: ='Đầu Vào'!E19 -> 50
A42: Chi phí NS/KH/tháng | B42: =IF('Đầu Vào'!$B$8="Mô hình 1",'Đầu Vào'!$I$9,'Đầu Vào'!$N$9)*'Đầu Vào'!$B$34 -> 13.8 | C42: =IF('Đầu Vào'!$B$8="Mô hình 1",'Đầu Vào'!$J$9,'Đầu Vào'!$O$9)*'Đầu Vào'!$B$34 -> 28.75 | D42: =IF('Đầu Vào'!$B$8="Mô hình 1",'Đầu Vào'!$K$9,'Đầu Vào'!$P$9)*'Đầu Vào'!$B$34 -> 60.375
A43: Chi phí tools/KH | B43: =IFERROR('Đầu Vào'!$B$41/'Đầu Vào'!$F$12,0) -> 0.8125 | C43: =IFERROR('Đầu Vào'!$B$41/'Đầu Vào'!$F$12,0) -> 0.8125 | D43: =IFERROR('Đầu Vào'!$B$41/'Đầu Vào'!$F$12,0) -> 0.8125
A44: Lợi nhuận gộp/KH | B44: =B41-B42-B43 -> -4.6125 | C44: =C41-C42-C43 -> -4.5625 | D44: =D41-D42-D43 -> -11.1875
...

Sheet UE G5-G7
A1: UNIT ECONOMICS – GÓI 5 ĐẾ N 7
A3: G5 – BC Digital Brand™
A4: Chỉ số | B4: Cơ Bản | C4: Tiêu Chuẩn | D4: Cao Cấp
A5: DT/dự án | B5: ='Đầu Vào'!C20 -> 20 | C5: ='Đầu Vào'!D20 -> 47.5 | D5: ='Đầu Vào'!E20 -> 95
A6: CP NS/dự án | B6: =IF('Đầu Vào'!$B$9="Mô hình 1",'Đầu Vào'!$I$10,'Đầu Vào'!$N$10)*'Đầu Vào'!$B$34 -> 17.25 | C6: =IF('Đầu Vào'!$B$9="Mô hình 1",'Đầu Vào'!$J$10,'Đầu Vào'!$O$10)*'Đầu Vào'!$B$34 -> 39.1 | D6: =IF('Đầu Vào'!$B$9="Mô hình 1",'Đầu Vào'!$K$10,'Đầu Vào'!$P$10)*'Đầu Vào'!$B$34 -> 77.625
A7: CP tools/dự án | B7: =IFERROR('Đầu Vào'!$B$41/'Đầu Vào'!$F$12,0) -> 0.8125 | C7: =IFERROR('Đầu Vào'!$B$41/'Đầu Vào'!$F$12,0) -> 0.8125 | D7: =IFERROR('Đầu Vào'!$B$41/'Đầu Vào'!$F$12,0) -> 0.8125
A8: LN gộp/dự án | B8: =B5-B6-B7 -> 1.9375 | C8: =C5-C6-C7 -> 7.5875 | D8: =D5-D6-D7 -> 16.5625
A9: Biên LN gộp (%) | B9: =IF(B5=0,0,B8/B5) -> 0.096875 | C9: =IF(C5=0,0,C8/C5) -> 0.15973684 | D9: =IF(D5=0,0,D8/D5) -> 0.17434211
A10: Số dự án/tháng | B10: ='Đầu Vào'!C9 -> 1 | C10: ='Đầu Vào'!D9 -> 0 | D10: ='Đầu Vào'!E9 -> 0
A11: DT tổng/tháng | B11: =B5*B10 -> 20 | C11: =C5*C10 -> 0 | D11: =D5*D10 -> 0
A12: LN tổng/tháng | B12: =B8*B10 -> 1.9375 | C12: =C8*C10 -> 0 | D12: =D8*D10 -> 0
A14: G6 – BC Marketing Automation™
A15: Chỉ số | B15: Cơ Bản | C15: Tiêu Chuẩn | D15: Cao Cấp
A16: Phí setup (1 lần) | B16: ='Đầu Vào'!C23 -> 12.5 | C16: ='Đầu Vào'!D23 -> 27.5 | D16: ='Đầu Vào'!E23 -> 65
A17: DT hàng tháng/KH | B17: ='Đầu Vào'!C21 -> 6.5 | C17: ='Đầu Vào'!D21 -> 16 | D17: ='Đầu Vào'!E21 -> 35
A18: CP NS/KH/tháng | B18: =IF('Đầu Vào'!$B$10="Mô hình 1",'Đầu Vào'!$I$11,'Đầu Vào'!$N$11)*'Đầu Vào'!$B$34 -> 27.025 | C18: =IF('Đầu Vào'!$B$10="Mô hình 1",'Đầu Vào'!$J$11,'Đầu Vào'!$O$11)*'Đầu Vào'!$B$34 -> 44.275 | D18: =IF('Đầu Vào'!$B$10="Mô hình 1",'Đầu Vào'!$K$11,'Đầu Vào'!$P$11)*'Đầu Vào'!$B$34 -> 71.3
A19: CP tools/KH | B19: =IFERROR('Đầu Vào'!$B$41/'Đầu Vào'!$F$12,0) -> 0.8125 | C19: =IFERROR('Đầu Vào'!$B$41/'Đầu Vào'!$F$12,0) -> 0.8125 | D19: =IFERROR('Đầu Vào'!$B$41/'Đầu Vào'!$F$12,0) -> 0.8125
A20: LN hàng tháng/KH | B20: =B17-B18-B19 -> -21.3375 | C20: =C17-C18-C19 -> -29.0875 | D20: =D17-D18-D19 -> -37.1125
A21: Biên LN tháng (%) | B21: =IF(B17=0,0,B20/B17) -> -3.2826923 | C21: =IF(C17=0,0,C20/C17) -> -1.8179687 | D21: =IF(D17=0,0,D20/D17) -> -1.0603571
A22: Tháng recover setup | B22: =IFERROR(ROUNDUP(B16/IF(B20<=0,0.001,B20),0),0) -> 12500 | C22: =IFERROR(ROUNDUP(C16/IF(C20<=0,0.001,C20),0),0) -> 27500 | D22: =IFERROR(ROUNDUP(D16/IF(D20<=0,0.001,D20),0),0) -> 65000
A23: Số KH | B23: ='Đầu Vào'!C10 -> 0 | C23: ='Đầu Vào'!D10 -> 0 | D23: ='Đầu Vào'!E10 -> 0
A24: DT tổng/tháng | B24: =B17*B23 -> 0 | C24: =C17*C23 -> 0 | D24: =D17*D23 -> 0
A25: LN tổng/tháng | B25: =B20*B23 -> 0 | C25: =C20*C23 -> 0 | D25: =D20*D23 -> 0
A27: G7 – BC Total Growth™
A28: Chỉ số | B28: Growth Starter | C28: Growth Pro | D28: Growth Enterprise
A29: DT/KH/tháng | B29: ='Đầu Vào'!C22 -> 45 | C29: ='Đầu Vào'!D22 -> 80 | D29: ='Đầu Vào'!E22 -> 160
A30: CP NS/KH/tháng | B30: =IF('Đầu Vào'!$B$11="Mô hình 1",'Đầu Vào'!$I$12,'Đầu Vào'!$N$12)*'Đầu Vào'!$B$34 -> 53.475 | C30: =IF('Đầu Vào'!$B$11="Mô hình 1",'Đầu Vào'!$J$12,'Đầu Vào'!$O$12)*'Đầu Vào'!$B$34 -> 87.4 | D30: =IF('Đầu Vào'!$B$11="Mô hình 1",'Đầu Vào'!$K$12,'Đầu Vào'!$P$12)*'Đầu Vào'!$B$34 -> 166.75
A31: LN gộp/KH | B31: =B29-B30 -> -8.475 | C31: =C29-C30 -> -7.4 | D31: =D29-D30 -> -6.75
A32: Biên LN gộp (%) | B32: =IF(B29=0,0,B31/B29) -> -0.18833333 | C32: =IF(C29=0,0,C31/C29) -> -0.0925 | D32: =IF(D29=0,0,D31/D29) -> -0.0421875
A33: FTE quy đổi | B33: =IFERROR(B30/('Đầu Vào'!$B$30*'Đầu Vào'!$B$34),0) -> 1.86 | C33: =IFERROR(C30/('Đầu Vào'!$B$30*'Đầu Vào'!$B$34),0) -> 3.04 | D33: =IFERROR(D30/('Đầu Vào'!$B$30*'Đầu Vào'!$B$34),0) -> 5.8
A34: DT/FTE (triệu) | B34: =IFERROR(B29/B33,0) -> 24.193548 | C34: =IFERROR(C29/C33,0) -> 26.315789 | D34: =IFERROR(D29/D33,0) -> 27.586207
A35: Số KH | B35: ='Đầu Vào'!C11 -> 0 | C35: ='Đầu Vào'!D11 -> 1 | D35: ='Đầu Vào'!E11 -> 0
A36: DT tổng/tháng | B36: =B29*B35 -> 0 | C36: =C29*C35 -> 80 | D36: =D29*D35 -> 0
A38: TÓM TẮT BIÊN LỢI NHUẬN GỘP
A39: Gói | B39: CB | C39: TC | D39: CC
A40: G5 – Digital Brand | B40: =B9 -> 0.096875 | C40: =C9 -> 0.15973684 | D40: =D9 -> 0.17434211
A41: G6 – Marketing Auto | B41: =B21 -> -3.2826923 | C41: =C21 -> -1.8179687 | D41: =D21 -> -1.0603571
A42: G7 – Total Growth | B42: =B32 -> -0.18833333 | C42: =C32 -> -0.0925 | D42: =D32 -> -0.0421875

Sheet P&L 12T
A1: BÁO CÁO LÃI LỖ DỰ KIẾ N 12 THÁNG (triệu VND)
A3: DOANH THU
A4: Hạng mục | B4: T1 | C4: T2 | D4: T3 | E4: T4 | F4: T5 | G4: T6 | H4: T7 | I4: T8 | J4: T9 | K4: T10 | L4: T11 | M4: T12 | N4: Tổng Năm
A5: G1 – BC Performance Ads™ | B5: =SUMPRODUCT('Đầu Vào'!C5:E5,'Đầu Vào'!C16:E16) -> 109 | C5: =B5*(1+'Đầu Vào'!$B$49-'Đầu Vào'!$B$50) -> 114.45 | D5: =C5*(1+'Đầu Vào'!$B$49-'Đầu Vào'!$B$50) -> 120.1725 | E5: =D5*(1+'Đầu Vào'!$B$49-'Đầu Vào'!$B$50) -> 126.18112 | F5: =E5*(1+'Đầu Vào'!$B$49-'Đầu Vào'!$B$50) -> 132.49018 | G5: =F5*(1+'Đầu Vào'!$B$49-'Đầu Vào'!$B$50) -> 139.11469 | H5: =G5*(1+'Đầu Vào'!$B$49-'Đầu Vào'!$B$50) -> 146.07042 | I5: =H5*(1+'Đầu Vào'!$B$49-'Đầu Vào'!$B$50) -> 153.37395 | J5: =I5*(1+'Đầu Vào'!$B$49-'Đầu Vào'!$B$50) -> 161.04264 | ... M5: =L5*(1+'Đầu Vào'!$B$49-'Đầu Vào'!$B$50) -> 186.42699 | N5: =SUM(B5:M5) -> 1734.9668
A6: G2 – BC SEO & Content™ | B6: =SUMPRODUCT('Đầu Vào'!C6:E6,'Đầu Vào'!C17:E17) -> 43 | C6: =B6*(1+'Đầu Vào'!$B$49-'Đầu Vào'!$B$50) -> 45.15 | D6: =C6*(1+'Đầu Vào'!$B$49-'Đầu Vào'!$B$50) -> 47.4075 | E6: =D6*(1+'Đầu Vào'!$B$49-'Đầu Vào'!$B$50) -> 49.777875 | F6: =E6*(1+'Đầu Vào'!$B$49-'Đầu Vào'!$B$50) -> 52.266769 | G6: =F6*(1+'Đầu Vào'!$B$49-'Đầu Vào'!$B$50) -> 54.880107 | H6: =G6*(1+'Đầu Vào'!$B$49-'Đầu Vào'!$B$50) -> 57.624113 | I6: =H6*(1+'Đầu Vào'!$B$49-'Đầu Vào'!$B$50) -> 60.505318 | J6: =I6*(1+'Đầu Vào'!$B$49-'Đầu Vào'!$B$50) -> 63.530584 | ... M6: =L6*(1+'Đầu Vào'!$B$49-'Đầu Vào'!$B$50) -> 73.544592 | N6: =SUM(B6:M6) -> 684.43644
A7: G3 – BC Social Media™ | B7: =SUMPRODUCT('Đầu Vào'!C7:E7,'Đầu Vào'!C18:E18) -> 34.5 | C7: =B7*(1+'Đầu Vào'!$B$49-'Đầu Vào'!$B$50) -> 36.225 | D7: =C7*(1+'Đầu Vào'!$B$49-'Đầu Vào'!$B$50) -> 38.03625 | E7: =D7*(1+'Đầu Vào'!$B$49-'Đầu Vào'!$B$50) -> 39.938063 | F7: =E7*(1+'Đầu Vào'!$B$49-'Đầu Vào'!$B$50) -> 41.934966 | G7: =F7*(1+'Đầu Vào'!$B$49-'Đầu Vào'!$B$50) -> 44.031714 | H7: =G7*(1+'Đầu Vào'!$B$49-'Đầu Vào'!$B$50) -> 46.2333 | I7: =H7*(1+'Đầu Vào'!$B$49-'Đầu Vào'!$B$50) -> 48.544965 | J7: =I7*(1+'Đầu Vào'!$B$49-'Đầu Vào'!$B$50) -> 50.972213 | ... M7: =L7*(1+'Đầu Vào'!$B$49-'Đầu Vào'!$B$50) -> 59.006708 | N7: =SUM(B7:M7) -> 549.14086
A8: G4 – BC TikTok & Social Commerce™ | B8: =SUMPRODUCT('Đầu Vào'!C8:E8,'Đầu Vào'!C19:E19) -> 35 | C8: =B8*(1+'Đầu Vào'!$B$49-'Đầu Vào'!$B$50) -> 36.75 | D8: =C8*(1+'Đầu Vào'!$B$49-'Đầu Vào'!$B$50) -> 38.5875 | E8: =D8*(1+'Đầu Vào'!$B$49-'Đầu Vào'!$B$50) -> 40.516875 | F8: =E8*(1+'Đầu Vào'!$B$49-'Đầu Vào'!$B$50) -> 42.542719 | G8: =F8*(1+'Đầu Vào'!$B$49-'Đầu Vào'!$B$50) -> 44.669855 | H8: =G8*(1+'Đầu Vào'!$B$49-'Đầu Vào'!$B$50) -> 46.903347 | I8: =H8*(1+'Đầu Vào'!$B$49-'Đầu Vào'!$B$50) -> 49.248515 | J8: =I8*(1+'Đầu Vào'!$B$49-'Đầu Vào'!$B$50) -> 51.710941 | ... M8: =L8*(1+'Đầu Vào'!$B$49-'Đầu Vào'!$B$50) -> 59.861878 | N8: =SUM(B8:M8) -> 557.09943
A9: G5 – BC Digital Brand™ | B9: =SUMPRODUCT('Đầu Vào'!C9:E9,'Đầu Vào'!C20:E20) -> 20 | C9: =B9*(1+'Đầu Vào'!$B$49-'Đầu Vào'!$B$50) -> 21 | D9: =C9*(1+'Đầu Vào'!$B$49-'Đầu Vào'!$B$50) -> 22.05 | E9: =D9*(1+'Đầu Vào'!$B$49-'Đầu Vào'!$B$50) -> 23.1525 | F9: =E9*(1+'Đầu Vào'!$B$49-'Đầu Vào'!$B$50) -> 24.310125 | G9: =F9*(1+'Đầu Vào'!$B$49-'Đầu Vào'!$B$50) -> 25.525631 | H9: =G9*(1+'Đầu Vào'!$B$49-'Đầu Vào'!$B$50) -> 26.801913 | I9: =H9*(1+'Đầu Vào'!$B$49-'Đầu Vào'!$B$50) -> 28.142008 | J9: =I9*(1+'Đầu Vào'!$B$49-'Đầu Vào'!$B$50) -> 29.549109 | ... M9: =L9*(1+'Đầu Vào'!$B$49-'Đầu Vào'!$B$50) -> 34.206787 | N9: =SUM(B9:M9) -> 318.34253
A10: G6 – BC Marketing Automation™ | B10: =SUMPRODUCT('Đầu Vào'!C10:E10,'Đầu Vào'!C21:E21) -> 0 | C10: =B10*(1+'Đầu Vào'!$B$49-'Đầu Vào'!$B$50) -> 0 | D10: =C10*(1+'Đầu Vào'!$B$49-'Đầu Vào'!$B$50) -> 0 | E10: =D10*(1+'Đầu Vào'!$B$49-'Đầu Vào'!$B$50) -> 0 | F10: =E10*(1+'Đầu Vào'!$B$49-'Đầu Vào'!$B$50) -> 0 | G10: =F10*(1+'Đầu Vào'!$B$49-'Đầu Vào'!$B$50) -> 0 | H10: =G10*(1+'Đầu Vào'!$B$49-'Đầu Vào'!$B$50) -> 0 | I10: =H10*(1+'Đầu Vào'!$B$49-'Đầu Vào'!$B$50) -> 0 | J10: =I10*(1+'Đầu Vào'!$B$49-'Đầu Vào'!$B$50) -> 0 | ... M10: =L10*(1+'Đầu Vào'!$B$49-'Đầu Vào'!$B$50) -> 0 | N10: =SUM(B10:M10) -> 0
A11: G7 – BC Total Growth™ | B11: =SUMPRODUCT('Đầu Vào'!C11:E11,'Đầu Vào'!C22:E22) -> 80 | C11: =B11*(1+'Đầu Vào'!$B$49-'Đầu Vào'!$B$50) -> 84 | D11: =C11*(1+'Đầu Vào'!$B$49-'Đầu Vào'!$B$50) -> 88.2 | E11: =D11*(1+'Đầu Vào'!$B$49-'Đầu Vào'!$B$50) -> 92.61 | F11: =E11*(1+'Đầu Vào'!$B$49-'Đầu Vào'!$B$50) -> 97.2405 | G11: =F11*(1+'Đầu Vào'!$B$49-'Đầu Vào'!$B$50) -> 102.10252 | H11: =G11*(1+'Đầu Vào'!$B$49-'Đầu Vào'!$B$50) -> 107.20765 | I11: =H11*(1+'Đầu Vào'!$B$49-'Đầu Vào'!$B$50) -> 112.56803 | J11: =I11*(1+'Đầu Vào'!$B$49-'Đầu Vào'!$B$50) -> 118.19644 | ... M11: =L11*(1+'Đầu Vào'!$B$49-'Đầu Vào'!$B$50) -> 136.82715 | N11: =SUM(B11:M11) -> 1273.3701
A12: TỔNG DOANH THU | B12: =SUM(B5:B11) -> 321.5 | C12: =SUM(C5:C11) -> 337.575 | D12: =SUM(D5:D11) -> 354.45375 | E12: =SUM(E5:E11) -> 372.17644 | F12: =SUM(F5:F11) -> 390.78526 | G12: =SUM(G5:G11) -> 410.32452 | H12: =SUM(H5:H11) -> 430.84075 | I12: =SUM(I5:I11) -> 452.38279 | ... N12: =SUM(N5:N11) -> 5117.3562
A14: CHI PHÍ NHÂN SỰ
A15: G1 – BC Performance Ads™ | B15: =(IF('Đầu Vào'!$B$5="Mô hình 1",'Đầu Vào'!I6,'Đầu Vào'!N6)*'Đầu Vào'!C5+IF('Đầu Vào'!$B$5="Mô hình 1",'Đầu Vào'!J6,'Đầu Vào'!O6)*'Đầu Vào'!D5+IF('Đầu Vào'!$B$5="Mô hình 1",'Đầu Vào'!K6,'Đầu Vào'!P6)*'Đầu Vào'!E5)*'Đầu Vào'!$B$34 -> 80.5 | C15: =B15*(1+'Đầu Vào'!$B$49-'Đầu Vào'!$B$50) -> 84.525 | D15: =C15*(1+'Đầu Vào'!$B$49-'Đầu Vào'!$B$50) -> 88.75125 | E15: =D15*(1+'Đầu Vào'!$B$49-'Đầu Vào'!$B$50) -> 93.188812 | F15: =E15*(1+'Đầu Vào'!$B$49-'Đầu Vào'!$B$50) -> 97.848253 | G15: =F15*(1+'Đầu Vào'!$B$49-'Đầu Vào'!$B$50) -> 102.74067 | H15: =G15*(1+'Đầu Vào'!$B$49-'Đầu Vào'!$B$50) -> 107.8777 | I15: =H15*(1+'Đầu Vào'!$B$49-'Đầu Vào'!$B$50) -> 113.27158 | J15: =I15*(1+'Đầu Vào'!$B$49-'Đầu Vào'!$B$50) -> 118.93516 | ... M15: =L15*(1+'Đầu Vào'!$B$49-'Đầu Vào'!$B$50) -> 137.68232 | N15: =SUM(B15:M15) -> 1281.3287
A16: G2 – BC SEO & Content™ | B16: =(IF('Đầu Vào'!$B$6="Mô hình 1",'Đầu Vào'!I7,'Đầu Vào'!N7)*'Đầu Vào'!C6+IF('Đầu Vào'!$B$6="Mô hình 1",'Đầu Vào'!J7,'Đầu Vào'!O7)*'Đầu Vào'!D6+IF('Đầu Vào'!$B$6="Mô hình 1",'Đầu Vào'!K7,'Đầu Vào'!P7)*'Đầu Vào'!E6)*'Đầu Vào'!$B$34 -> 32.2 | C16: =B16*(1+'Đầu Vào'!$B$49-'Đầu Vào'!$B$50) -> 33.81 | D16: =C16*(1+'Đầu Vào'!$B$49-'Đầu Vào'!$B$50) -> 35.5005 | E16: =D16*(1+'Đầu Vào'!$B$49-'Đầu Vào'!$B$50) -> 37.275525 | F16: =E16*(1+'Đầu Vào'!$B$49-'Đầu Vào'!$B$50) -> 39.139301 | G16: =F16*(1+'Đầu Vào'!$B$49-'Đầu Vào'!$B$50) -> 41.096266 | H16: =G16*(1+'Đầu Vào'!$B$49-'Đầu Vào'!$B$50) -> 43.15108 | I16: =H16*(1+'Đầu Vào'!$B$49-'Đầu Vào'!$B$50) -> 45.308634 | J16: =I16*(1+'Đầu Vào'!$B$49-'Đầu Vào'!$B$50) -> 47.574065 | ... M16: =L16*(1+'Đầu Vào'!$B$49-'Đầu Vào'!$B$50) -> 55.072927 | N16: =SUM(B16:M16) -> 512.53147
A17: G3 – BC Social Media™ | B17: =(IF('Đầu Vào'!$B$7="Mô hình 1",'Đầu Vào'!I8,'Đầu Vào'!N8)*'Đầu Vào'!C7+IF('Đầu Vào'!$B$7="Mô hình 1",'Đầu Vào'!J8,'Đầu Vào'!O8)*'Đầu Vào'!D7+IF('Đầu Vào'!$B$7="Mô hình 1",'Đầu Vào'!K8,'Đầu Vào'!P8)*'Đầu Vào'!E7)*'Đầu Vào'!$B$34 -> 41.975 | C17: =B17*(1+'Đầu Vào'!$B$49-'Đầu Vào'!$B$50) -> 44.07375 | D17: =C17*(1+'Đầu Vào'!$B$49-'Đầu Vào'!$B$50) -> 46.277437 | E17: =D17*(1+'Đầu Vào'!$B$49-'Đầu Vào'!$B$50) -> 48.591309 | F17: =E17*(1+'Đầu Vào'!$B$49-'Đầu Vào'!$B$50) -> 51.020875 | G17: =F17*(1+'Đầu Vào'!$B$49-'Đầu Vào'!$B$50) -> 53.571919 | H17: =G17*(1+'Đầu Vào'!$B$49-'Đầu Vào'!$B$50) -> 56.250515 | I17: =H17*(1+'Đầu Vào'!$B$49-'Đầu Vào'!$B$50) -> 59.06304 | J17: =I17*(1+'Đầu Vào'!$B$49-'Đầu Vào'!$B$50) -> 62.016192 | ... M17: =L17*(1+'Đầu Vào'!$B$49-'Đầu Vào'!$B$50) -> 71.791495 | N17: =SUM(B17:M17) -> 668.12139
A18: G4 – BC TikTok & Social Commerce™ | B18: =(IF('Đầu Vào'!$B$8="Mô hình 1",'Đầu Vào'!I9,'Đầu Vào'!N9)*'Đầu Vào'!C8+IF('Đầu Vào'!$B$8="Mô hình 1",'Đầu Vào'!J9,'Đầu Vào'!O9)*'Đầu Vào'!D8+IF('Đầu Vào'!$B$8="Mô hình 1",'Đầu Vào'!K9,'Đầu Vào'!P9)*'Đầu Vào'!E8)*'Đầu Vào'!$B$34 -> 42.55 | C18: =B18*(1+'Đầu Vào'!$B$49-'Đầu Vào'!$B$50) -> 44.6775 | D18: =C18*(1+'Đầu Vào'!$B$49-'Đầu Vào'!$B$50) -> 46.911375 | E18: =D18*(1+'Đầu Vào'!$B$49-'Đầu Vào'!$B$50) -> 49.256944 | F18: =E18*(1+'Đầu Vào'!$B$49-'Đầu Vào'!$B$50) -> 51.719791 | G18: =F18*(1+'Đầu Vào'!$B$49-'Đầu Vào'!$B$50) -> 54.30578 | H18: =G18*(1+'Đầu Vào'!$B$49-'Đầu Vào'!$B$50) -> 57.02107 | I18: =H18*(1+'Đầu Vào'!$B$49-'Đầu Vào'!$B$50) -> 59.872123 | J18: =I18*(1+'Đầu Vào'!$B$49-'Đầu Vào'!$B$50) -> 62.865729 | ... M18: =L18*(1+'Đầu Vào'!$B$49-'Đầu Vào'!$B$50) -> 72.77494 | N18: =SUM(B18:M18) -> 677.27373
A19: G5 – BC Digital Brand™ | B19: =(IF('Đầu Vào'!$B$9="Mô hình 1",'Đầu Vào'!I10,'Đầu Vào'!N10)*'Đầu Vào'!C9+IF('Đầu Vào'!$B$9="Mô hình 1",'Đầu Vào'!J10,'Đầu Vào'!O10)*'Đầu Vào'!D9+IF('Đầu Vào'!$B$9="Mô hình 1",'Đầu Vào'!K10,'Đầu Vào'!P10)*'Đầu Vào'!E9)*'Đầu Vào'!$B$34 -> 17.25 | C19: =B19*(1+'Đầu Vào'!$B$49-'Đầu Vào'!$B$50) -> 18.1125 | D19: =C19*(1+'Đầu Vào'!$B$49-'Đầu Vào'!$B$50) -> 19.018125 | E19: =D19*(1+'Đầu Vào'!$B$49-'Đầu Vào'!$B$50) -> 19.969031 | F19: =E19*(1+'Đầu Vào'!$B$49-'Đầu Vào'!$B$50) -> 20.967483 | G19: =F19*(1+'Đầu Vào'!$B$49-'Đầu Vào'!$B$50) -> 22.015857 | H19: =G19*(1+'Đầu Vào'!$B$49-'Đầu Vào'!$B$50) -> 23.11665 | I19: =H19*(1+'Đầu Vào'!$B$49-'Đầu Vào'!$B$50) -> 24.272482 | J19: =I19*(1+'Đầu Vào'!$B$49-'Đầu Vào'!$B$50) -> 25.486106 | ... M19: =L19*(1+'Đầu Vào'!$B$49-'Đầu Vào'!$B$50) -> 29.503354 | N19: =SUM(B19:M19) -> 274.57043
A20: G6 – BC Marketing Automation™ | B20: =(IF('Đầu Vào'!$B$10="Mô hình 1",'Đầu Vào'!I11,'Đầu Vào'!N11)*'Đầu Vào'!C10+IF('Đầu Vào'!$B$10="Mô hình 1",'Đầu Vào'!J11,'Đầu Vào'!O11)*'Đầu Vào'!D10+IF('Đầu Vào'!$B$10="Mô hình 1",'Đầu Vào'!K11,'Đầu Vào'!P11)*'Đầu Vào'!E10)*'Đầu Vào'!$B$34 -> 0 | C20: =B20*(1+'Đầu Vào'!$B$49-'Đầu Vào'!$B$50) -> 0 | D20: =C20*(1+'Đầu Vào'!$B$49-'Đầu Vào'!$B$50) -> 0 | E20: =D20*(1+'Đầu Vào'!$B$49-'Đầu Vào'!$B$50) -> 0 | F20: =E20*(1+'Đầu Vào'!$B$49-'Đầu Vào'!$B$50) -> 0 | G20: =F20*(1+'Đầu Vào'!$B$49-'Đầu Vào'!$B$50) -> 0 | H20: =G20*(1+'Đầu Vào'!$B$49-'Đầu Vào'!$B$50) -> 0 | I20: =H20*(1+'Đầu Vào'!$B$49-'Đầu Vào'!$B$50) -> 0 | J20: =I20*(1+'Đầu Vào'!$B$49-'Đầu Vào'!$B$50) -> 0 | ... M20: =L20*(1+'Đầu Vào'!$B$49-'Đầu Vào'!$B$50) -> 0 | N20: =SUM(B20:M20) -> 0
A21: G7 – BC Total Growth™ | B21: =(IF('Đầu Vào'!$B$11="Mô hình 1",'Đầu Vào'!I12,'Đầu Vào'!N12)*'Đầu Vào'!C11+IF('Đầu Vào'!$B$11="Mô hình 1",'Đầu Vào'!J12,'Đầu Vào'!O12)*'Đầu Vào'!D11+IF('Đầu Vào'!$B$11="Mô hình 1",'Đầu Vào'!K12,'Đầu Vào'!P12)*'Đầu Vào'!E11)*'Đầu Vào'!$B$34 -> 87.4 | C21: =B21*(1+'Đầu Vào'!$B$49-'Đầu Vào'!$B$50) -> 91.77 | D21: =C21*(1+'Đầu Vào'!$B$49-'Đầu Vào'!$B$50) -> 96.3585 | E21: =D21*(1+'Đầu Vào'!$B$49-'Đầu Vào'!$B$50) -> 101.17642 | F21: =E21*(1+'Đầu Vào'!$B$49-'Đầu Vào'!$B$50) -> 106.23525 | G21: =F21*(1+'Đầu Vào'!$B$49-'Đầu Vào'!$B$50) -> 111.54701 | H21: =G21*(1+'Đầu Vào'!$B$49-'Đầu Vào'!$B$50) -> 117.12436 | I21: =H21*(1+'Đầu Vào'!$B$49-'Đầu Vào'!$B$50) -> 122.98058 | J21: =I21*(1+'Đầu Vào'!$B$49-'Đầu Vào'!$B$50) -> 129.12961 | ... M21: =L21*(1+'Đầu Vào'!$B$49-'Đầu Vào'!$B$50) -> 149.48366 | N21: =SUM(B21:M21) -> 1391.1569
A22: TỔNG CHI PHÍ NS | B22: =SUM(B15:B21) -> 301.875 | C22: =SUM(C15:C21) -> 316.96875 | D22: =SUM(D15:D21) -> 332.81719 | E22: =SUM(E15:E21) -> 349.45805 | F22: =SUM(F15:F21) -> 366.93095 | G22: =SUM(G15:G21) -> 385.2775 | H22: =SUM(H15:H21) -> 404.54137 | I22: =SUM(I15:I21) -> 424.76844 | ... N22: =SUM(N15:N21) -> 4804.9826
A24: LỢI NHUẬN GỘP | B24: =B12-B22 -> 19.625 | C24: =C12-C22 -> 20.60625 | D24: =D12-D22 -> 21.636563 | E24: =E12-E22 -> 22.718391 | F24: =F12-F22 -> 23.85431 | G24: =G12-G22 -> 25.047026 | H24: =H12-H22 -> 26.299377 | I24: =I12-I22 -> 27.614346 | ... N24: =N12-N22 -> 312.37361
A25: Biên LN gộp (%) | B25: =IF(B12=0,0,B24/B12) -> 0.061041991 | C25: =IF(C12=0,0,C24/C12) -> 0.061041991 | D25: =IF(D12=0,0,D24/D12) -> 0.061041991 | E25: =IF(E12=0,0,E24/E12) -> 0.061041991 | F25: =IF(F12=0,0,F24/F12) -> 0.061041991 | G25: =IF(G12=0,0,G24/G12) -> 0.061041991 | H25: =IF(H12=0,0,H24/H12) -> 0.061041991 | I25: =IF(I12=0,0,I24/I12) -> 0.061041991 | ... N25: =IF(N12=0,0,N24/N12) -> 0.061041991
A27: CHI PHÍ CỐ ĐỊNH HÀNG THÁNG
A28: Chi phí công cụ SaaS | B28: ='Đầu Vào'!$B$41 -> 13 | C28: ='Đầu Vào'!$B$41 -> 13 | D28: ='Đầu Vào'!$B$41 -> 13 | E28: ='Đầu Vào'!$B$41 -> 13 | F28: ='Đầu Vào'!$B$41 -> 13 | G28: ='Đầu Vào'!$B$41 -> 13 | H28: ='Đầu Vào'!$B$41 -> 13 | I28: ='Đầu Vào'!$B$41 -> 13 | ... M28: ='Đầu Vào'!$B$41 -> 13 | N28: =SUM(B28:M28) -> 156
A29: Thuê văn phòng | B29: ='Đầu Vào'!$B$39 -> 15 | C29: ='Đầu Vào'!$B$39 -> 15 | D29: ='Đầu Vào'!$B$39 -> 15 | E29: ='Đầu Vào'!$B$39 -> 15 | F29: ='Đầu Vào'!$B$39 -> 15 | G29: ='Đầu Vào'!$B$39 -> 15 | H29: ='Đầu Vào'!$B$39 -> 15 | I29: ='Đầu Vào'!$B$39 -> 15 | ... M29: ='Đầu Vào'!$B$39 -> 15 | N29: =SUM(B29:M29) -> 180
A30: Lương BGĐ | B30: ='Đầu Vào'!$B$40 -> 30 | C30: ='Đầu Vào'!$B$40 -> 30 | D30: ='Đầu Vào'!$B$40 -> 30 | E30: ='Đầu Vào'!$B$40 -> 30 | F30: ='Đầu Vào'!$B$40 -> 30 | G30: ='Đầu Vào'!$B$40 -> 30 | H30: ='Đầu Vào'!$B$40 -> 30 | I30: ='Đầu Vào'!$B$40 -> 30 | ... M30: ='Đầu Vào'!$B$40 -> 30 | N30: =SUM(B30:M30) -> 360
A31: Chi phí khác | B31: ='Đầu Vào'!$B$42 -> 5 | C31: ='Đầu Vào'!$B$42 -> 5 | D31: ='Đầu Vào'!$B$42 -> 5 | E31: ='Đầu Vào'!$B$42 -> 5 | F31: ='Đầu Vào'!$B$42 -> 5 | G31: ='Đầu Vào'!$B$42 -> 5 | H31: ='Đầu Vào'!$B$42 -> 5 | I31: ='Đầu Vào'!$B$42 -> 5 | ... M31: ='Đầu Vào'!$B$42 -> 5 | N31: =SUM(B31:M31) -> 60
A32: Khấu hao | B32: ='Đầu Vào'!$B$43 -> 3 | C32: ='Đầu Vào'!$B$43 -> 3 | D32: ='Đầu Vào'!$B$43 -> 3 | E32: ='Đầu Vào'!$B$43 -> 3 | F32: ='Đầu Vào'!$B$43 -> 3 | G32: ='Đầu Vào'!$B$43 -> 3 | H32: ='Đầu Vào'!$B$43 -> 3 | I32: ='Đầu Vào'!$B$43 -> 3 | ... M32: ='Đầu Vào'!$B$43 -> 3 | N32: =SUM(B32:M32) -> 36
A33: Marketing | B33: ='Đầu Vào'!$B$44 -> 5 | C33: ='Đầu Vào'!$B$44 -> 5 | D33: ='Đầu Vào'!$B$44 -> 5 | E33: ='Đầu Vào'!$B$44 -> 5 | F33: ='Đầu Vào'!$B$44 -> 5 | G33: ='Đầu Vào'!$B$44 -> 5 | H33: ='Đầu Vào'!$B$44 -> 5 | I33: ='Đầu Vào'!$B$44 -> 5 | ... M33: ='Đầu Vào'!$B$44 -> 5 | N33: =SUM(B33:M33) -> 60
A34: TỔNG CP CỐ ĐỊNH | B34: =SUM(B28:B33) -> 71 | C34: =SUM(C28:C33) -> 71 | D34: =SUM(D28:D33) -> 71 | E34: =SUM(E28:E33) -> 71 | F34: =SUM(F28:F33) -> 71 | G34: =SUM(G28:G33) -> 71 | H34: =SUM(H28:H33) -> 71 | I34: =SUM(I28:I33) -> 71 | ... N34: =SUM(N28:N33) -> 852
A36: EBITDA | B36: =B24-B34 -> -51.375 | C36: =C24-C34 -> -50.39375 | D36: =D24-D34 -> -49.363438 | E36: =E24-E34 -> -48.281609 | F36: =F24-F34 -> -47.14569 | G36: =G24-G34 -> -45.952974 | H36: =H24-H34 -> -44.700623 | I36: =I24-I34 -> -43.385654 | ... N36: =N24-N34 -> -539.62639
A37: EBITDA Margin (%) | B37: =IF(B12=0,0,B36/B12) -> -0.15979782 | C37: =IF(C12=0,0,C36/C12) -> -0.14928164 | D37: =IF(D12=0,0,D36/D12) -> -0.13926623 | E37: =IF(E12=0,0,E36/E12) -> -0.12972774 | F37: =IF(F12=0,0,F36/F12) -> -0.12064347 | G37: =IF(G12=0,0,G36/G12) -> -0.11199178 | H37: =IF(H12=0,0,H36/H12) -> -0.10375208 | I37: =IF(I12=0,0,I36/I12) -> -0.095904742 | ... N37: =IF(N12=0,0,N36/N12) -> -0.10545023
A39: SỐ KH TỔNG | B39: ='Đầu Vào'!$F$12 -> 16 | C39: =ROUND(B39*(1+'Đầu Vào'!$B$49-'Đầu Vào'!$B$50),0) -> 17 | D39: =ROUND(C39*(1+'Đầu Vào'!$B$49-'Đầu Vào'!$B$50),0) -> 18 | E39: =ROUND(D39*(1+'Đầu Vào'!$B$49-'Đầu Vào'!$B$50),0) -> 19 | F39: =ROUND(E39*(1+'Đầu Vào'!$B$49-'Đầu Vào'!$B$50),0) -> 20 | G39: =ROUND(F39*(1+'Đầu Vào'!$B$49-'Đầu Vào'!$B$50),0) -> 21 | H39: =ROUND(G39*(1+'Đầu Vào'!$B$49-'Đầu Vào'!$B$50),0) -> 22 | I39: =ROUND(H39*(1+'Đầu Vào'!$B$49-'Đầu Vào'!$B$50),0) -> 23 | J39: =ROUND(I39*(1+'Đầu Vào'!$B$49-'Đầu Vào'!$B$50),0) -> 24 | ... M39: =ROUND(L39*(1+'Đầu Vào'!$B$49-'Đầu Vào'!$B$50),0) -> 27 | N39: =M39 -> 27
A40: DOANH THU / NHÂN VIÊN | B40: =IFERROR(B12/'Đầu Vào'!$B$35,0) -> 64.3 | C40: =IFERROR(C12/'Đầu Vào'!$B$35,0) -> 67.515 | D40: =IFERROR(D12/'Đầu Vào'!$B$35,0) -> 70.89075 | E40: =IFERROR(E12/'Đầu Vào'!$B$35,0) -> 74.435288 | F40: =IFERROR(F12/'Đầu Vào'!$B$35,0) -> 78.157052 | G40: =IFERROR(G12/'Đầu Vào'!$B$35,0) -> 82.064904 | H40: =IFERROR(H12/'Đầu Vào'!$B$35,0) -> 86.16815 | I40: =IFERROR(I12/'Đầu Vào'!$B$35,0) -> 90.476557 | ... N40: =IFERROR(N12/'Đầu Vào'!$B$35,0) -> 1023.4712

Sheet Hòa Vốn
A1: PHÂN TÍCH HÒA VỐN
A3: HÒA VỐN THEO SỐ KHÁCH HÀNG
A4: Tổng doanh thu tháng | B4: ='P&L 12T'!B12 -> 321.5
A5: Tổng chi phí NS tháng | B5: ='P&L 12T'!B22 -> 301.875
A6: Tổng chi phí cố định | B6: ='Đầu Vào'!$B$45 -> 71
A7: Số KH hiện tại | B7: ='Đầu Vào'!$F$12 -> 16
A8: DT bình quân/KH | B8: =IFERROR(B4/B7,0) -> 20.09375
A9: CP NS bình quân/KH | B9: =IFERROR(B5/B7,0) -> 18.867188
A10: Contribution margin/KH | B10: =B8-B9 -> 1.2265625
A11: SỐ KH HÒA VỐN | B11: =IFERROR(ROUNDUP(B6/IF(B10<=0,0.001,B10),0),0) -> 58
A12: Cần thêm (so với hiện tại) | B12: =IF(B11>B7,B11-B7,0) -> 42
A14: HÒA VỐN THEO THỜI GIAN
A15: EBITDA tháng 1 | B15: ='P&L 12T'!B36 -> -51.375
A16: Tốc độ tăng trưởng ròng/tháng | B16: ='Đầu Vào'!$B$49-'Đầu Vào'!$B$50 -> 0.05
A17: THÁNG DỰ KIẾ N HÒA VỐN | B17: =IF('P&L 12T'!B36>=0,1,IF('P&L 12T'!B12-'P&L 12T'!B22<=0,0,IFERROR(ROUNDUP(1+LOG('Đầu Vào'!$B$45/('P&L 12T'!B12-'P&L 12T'!B22))/LOG(1+'Đầu Vào'!$B$49-'Đầu Vào'!$B$50),0),0))) -> 28
A19: ĐỘ NHẠY BIÊN EBITDA: GIÁ vs CHI PHÍ NS
A20: Thay đổi giá ↓ \ Thay đổi CP NS → | B20: -0.2 | C20: -0.1 | D20: 0 | E20: 0.1 | F20: 0.2
A21: -0.2 | B21: =IFERROR(('P&L 12T'!$B$12*(1+$A21)-'P&L 12T'!$B$22*(1+B$20)-'Đầu Vào'!$B$45)/IF('P&L 12T'!$B$12*(1+$A21)=0,1,'P&L 12T'!$B$12*(1+$A21)),0) -> -0.21500778 | C21: =IFERROR(('P&L 12T'!$B$12*(1+$A21)-'P&L 12T'!$B$22*(1+C$20)-'Đầu Vào'!$B$45)/IF('P&L 12T'!$B$12*(1+$A21)=0,1,'P&L 12T'!$B$12*(1+$A21)),0) -> -0.33237753 | D21: =IFERROR(('P&L 12T'!$B$12*(1+$A21)-'P&L 12T'!$B$22*(1+D$20)-'Đầu Vào'!$B$45)/IF('P&L 12T'!$B$12*(1+$A21)=0,1,'P&L 12T'!$B$12*(1+$A21)),0) -> -0.44974728 | E21: =IFERROR(('P&L 12T'!$B$12*(1+$A21)-'P&L 12T'!$B$22*(1+E$20)-'Đầu Vào'!$B$45)/IF('P&L 12T'!$B$12*(1+$A21)=0,1,'P&L 12T'!$B$12*(1+$A21)),0) -> -0.56711703 | F21: =IFERROR(('P&L 12T'!$B$12*(1+$A21)-'P&L 12T'!$B$22*(1+F$20)-'Đầu Vào'!$B$45)/IF('P&L 12T'!$B$12*(1+$A21)=0,1,'P&L 12T'!$B$12*(1+$A21)),0) -> -0.68448678
A22: -0.1 | B22: =IFERROR(('P&L 12T'!$B$12*(1+$A22)-'P&L 12T'!$B$22*(1+B$20)-'Đầu Vào'!$B$45)/IF('P&L 12T'!$B$12*(1+$A22)=0,1,'P&L 12T'!$B$12*(1+$A22)),0) -> -0.080006912 | C22: =IFERROR(('P&L 12T'!$B$12*(1+$A22)-'P&L 12T'!$B$22*(1+C$20)-'Đầu Vào'!$B$45)/IF('P&L 12T'!$B$12*(1+$A22)=0,1,'P&L 12T'!$B$12*(1+$A22)),0) -> -0.18433558 | D22: =IFERROR(('P&L 12T'!$B$12*(1+$A22)-'P&L 12T'!$B$22*(1+D$20)-'Đầu Vào'!$B$45)/IF('P&L 12T'!$B$12*(1+$A22)=0,1,'P&L 12T'!$B$12*(1+$A22)),0) -> -0.28866425 | E22: =IFERROR(('P&L 12T'!$B$12*(1+$A22)-'P&L 12T'!$B$22*(1+E$20)-'Đầu Vào'!$B$45)/IF('P&L 12T'!$B$12*(1+$A22)=0,1,'P&L 12T'!$B$12*(1+$A22)),0) -> -0.39299292 | F22: =IFERROR(('P&L 12T'!$B$12*(1+$A22)-'P&L 12T'!$B$22*(1+F$20)-'Đầu Vào'!$B$45)/IF('P&L 12T'!$B$12*(1+$A22)=0,1,'P&L 12T'!$B$12*(1+$A22)),0) -> -0.49732158
A23: 0 | B23: =IFERROR(('P&L 12T'!$B$12*(1+$A23)-'P&L 12T'!$B$22*(1+B$20)-'Đầu Vào'!$B$45)/IF('P&L 12T'!$B$12*(1+$A23)=0,1,'P&L 12T'!$B$12*(1+$A23)),0) -> 0.027993779 | C23: =IFERROR(('P&L 12T'!$B$12*(1+$A23)-'P&L 12T'!$B$22*(1+C$20)-'Đầu Vào'!$B$45)/IF('P&L 12T'!$B$12*(1+$A23)=0,1,'P&L 12T'!$B$12*(1+$A23)),0) -> -0.065902022 | D23: =IFERROR(('P&L 12T'!$B$12*(1+$A23)-'P&L 12T'!$B$22*(1+D$20)-'Đầu Vào'!$B$45)/IF('P&L 12T'!$B$12*(1+$A23)=0,1,'P&L 12T'!$B$12*(1+$A23)),0) -> -0.15979782 | E23: =IFERROR(('P&L 12T'!$B$12*(1+$A23)-'P&L 12T'!$B$22*(1+E$20)-'Đầu Vào'!$B$45)/IF('P&L 12T'!$B$12*(1+$A23)=0,1,'P&L 12T'!$B$12*(1+$A23)),0) -> -0.25369362 | F23: =IFERROR(('P&L 12T'!$B$12*(1+$A23)-'P&L 12T'!$B$22*(1+F$20)-'Đầu Vào'!$B$45)/IF('P&L 12T'!$B$12*(1+$A23)=0,1,'P&L 12T'!$B$12*(1+$A23)),0) -> -0.34758942
A24: 0.1 | B24: =IFERROR(('P&L 12T'!$B$12*(1+$A24)-'P&L 12T'!$B$22*(1+B$20)-'Đầu Vào'!$B$45)/IF('P&L 12T'!$B$12*(1+$A24)=0,1,'P&L 12T'!$B$12*(1+$A24)),0) -> 0.11635798 | C24: =IFERROR(('P&L 12T'!$B$12*(1+$A24)-'P&L 12T'!$B$22*(1+C$20)-'Đầu Vào'!$B$45)/IF('P&L 12T'!$B$12*(1+$A24)=0,1,'P&L 12T'!$B$12*(1+$A24)),0) -> 0.030998162 | D24: =IFERROR(('P&L 12T'!$B$12*(1+$A24)-'P&L 12T'!$B$22*(1+D$20)-'Đầu Vào'!$B$45)/IF('P&L 12T'!$B$12*(1+$A24)=0,1,'P&L 12T'!$B$12*(1+$A24)),0) -> -0.054361657 | E24: =IFERROR(('P&L 12T'!$B$12*(1+$A24)-'P&L 12T'!$B$22*(1+E$20)-'Đầu Vào'!$B$45)/IF('P&L 12T'!$B$12*(1+$A24)=0,1,'P&L 12T'!$B$12*(1+$A24)),0) -> -0.13972148 | F24: =IFERROR(('P&L 12T'!$B$12*(1+$A24)-'P&L 12T'!$B$22*(1+F$20)-'Đầu Vào'!$B$45)/IF('P&L 12T'!$B$12*(1+$A24)=0,1,'P&L 12T'!$B$12*(1+$A24)),0) -> -0.2250813
A25: 0.2 | B25: =IFERROR(('P&L 12T'!$B$12*(1+$A25)-'P&L 12T'!$B$22*(1+B$20)-'Đầu Vào'!$B$45)/IF('P&L 12T'!$B$12*(1+$A25)=0,1,'P&L 12T'!$B$12*(1+$A25)),0) -> 0.18999482 | C25: =IFERROR(('P&L 12T'!$B$12*(1+$A25)-'P&L 12T'!$B$22*(1+C$20)-'Đầu Vào'!$B$45)/IF('P&L 12T'!$B$12*(1+$A25)=0,1,'P&L 12T'!$B$12*(1+$A25)),0) -> 0.11174832 | D25: =IFERROR(('P&L 12T'!$B$12*(1+$A25)-'P&L 12T'!$B$22*(1+D$20)-'Đầu Vào'!$B$45)/IF('P&L 12T'!$B$12*(1+$A25)=0,1,'P&L 12T'!$B$12*(1+$A25)),0) -> 0.033501814 | E25: =IFERROR(('P&L 12T'!$B$12*(1+$A25)-'P&L 12T'!$B$22*(1+E$20)-'Đầu Vào'!$B$45)/IF('P&L 12T'!$B$12*(1+$A25)=0,1,'P&L 12T'!$B$12*(1+$A25)),0) -> -0.044744686 | F25: =IFERROR(('P&L 12T'!$B$12*(1+$A25)-'P&L 12T'!$B$22*(1+F$20)-'Đầu Vào'!$B$45)/IF('P&L 12T'!$B$12*(1+$A25)=0,1,'P&L 12T'!$B$12*(1+$A25)),0) -> -0.12299119
A27: ĐỘ NHẠY BIÊN EBITDA: SỐ KH vs GIÁ
A28: Thay đổi số KH ↓ \ Thay đổi giá → | B28: -0.2 | C28: -0.1 | D28: 0 | E28: 0.1 | F28: 0.2
A29: -0.3 | B29: =IFERROR(('P&L 12T'!$B$12*(1+B$28)*(1+$A29)-'P&L 12T'!$B$22*(1+$A29)-'Đầu Vào'!$B$45)/IF('P&L 12T'!$B$12*(1+B$28)*(1+$A29)=0,1,'P&L 12T'!$B$12*(1+B$28)*(1+$A29)),0) -> -0.56805432 | C29: =IFERROR(('P&L 12T'!$B$12*(1+C$28)*(1+$A29)-'P&L 12T'!$B$22*(1+$A29)-'Đầu Vào'!$B$45)/IF('P&L 12T'!$B$12*(1+C$28)*(1+$A29)=0,1,'P&L 12T'!$B$12*(1+C$28)*(1+$A29)),0) -> -0.39382606 | D29: =IFERROR(('P&L 12T'!$B$12*(1+D$28)*(1+$A29)-'P&L 12T'!$B$22*(1+$A29)-'Đầu Vào'!$B$45)/IF('P&L 12T'!$B$12*(1+D$28)*(1+$A29)=0,1,'P&L 12T'!$B$12*(1+D$28)*(1+$A29)),0) -> -0.25444346 | E29: =IFERROR(('P&L 12T'!$B$12*(1+E$28)*(1+$A29)-'P&L 12T'!$B$22*(1+$A29)-'Đầu Vào'!$B$45)/IF('P&L 12T'!$B$12*(1+E$28)*(1+$A29)=0,1,'P&L 12T'!$B$12*(1+E$28)*(1+$A29)),0) -> -0.14040314 | F29: =IFERROR(('P&L 12T'!$B$12*(1+F$28)*(1+$A29)-'P&L 12T'!$B$22*(1+$A29)-'Đầu Vào'!$B$45)/IF('P&L 12T'!$B$12*(1+F$28)*(1+$A29)=0,1,'P&L 12T'!$B$12*(1+F$28)*(1+$A29)),0) -> -0.045369548
A30: -0.15 | B30: =IFERROR(('P&L 12T'!$B$12*(1+B$28)*(1+$A30)-'P&L 12T'!$B$22*(1+$A30)-'Đầu Vào'!$B$45)/IF('P&L 12T'!$B$12*(1+B$28)*(1+$A30)=0,1,'P&L 12T'!$B$12*(1+B$28)*(1+$A30)),0) -> -0.49846194 | C30: =IFERROR(('P&L 12T'!$B$12*(1+C$28)*(1+$A30)-'P&L 12T'!$B$22*(1+$A30)-'Đầu Vào'!$B$45)/IF('P&L 12T'!$B$12*(1+C$28)*(1+$A30)=0,1,'P&L 12T'!$B$12*(1+C$28)*(1+$A30)),0) -> -0.33196617 | D30: =IFERROR(('P&L 12T'!$B$12*(1+D$28)*(1+$A30)-'P&L 12T'!$B$22*(1+$A30)-'Đầu Vào'!$B$45)/IF('P&L 12T'!$B$12*(1+D$28)*(1+$A30)=0,1,'P&L 12T'!$B$12*(1+D$28)*(1+$A30)),0) -> -0.19876955 | E30: =IFERROR(('P&L 12T'!$B$12*(1+E$28)*(1+$A30)-'P&L 12T'!$B$22*(1+$A30)-'Đầu Vào'!$B$45)/IF('P&L 12T'!$B$12*(1+E$28)*(1+$A30)=0,1,'P&L 12T'!$B$12*(1+E$28)*(1+$A30)),0) -> -0.089790504 | F30: =IFERROR(('P&L 12T'!$B$12*(1+F$28)*(1+$A30)-'P&L 12T'!$B$22*(1+$A30)-'Đầu Vào'!$B$45)/IF('P&L 12T'!$B$12*(1+F$28)*(1+$A30)=0,1,'P&L 12T'!$B$12*(1+F$28)*(1+$A30)),0) -> 0.0010253713
A31: 0 | B31: =IFERROR(('P&L 12T'!$B$12*(1+B$28)*(1+$A31)-'P&L 12T'!$B$22*(1+$A31)-'Đầu Vào'!$B$45)/IF('P&L 12T'!$B$12*(1+B$28)*(1+$A31)=0,1,'P&L 12T'!$B$12*(1+B$28)*(1+$A31)),0) -> -0.44974728 | C31: =IFERROR(('P&L 12T'!$B$12*(1+C$28)*(1+$A31)-'P&L 12T'!$B$22*(1+$A31)-'Đầu Vào'!$B$45)/IF('P&L 12T'!$B$12*(1+C$28)*(1+$A31)=0,1,'P&L 12T'!$B$12*(1+C$28)*(1+$A31)),0) -> -0.28866425 | D31: =IFERROR(('P&L 12T'!$B$12*(1+D$28)*(1+$A31)-'P&L 12T'!$B$22*(1+$A31)-'Đầu Vào'!$B$45)/IF('P&L 12T'!$B$12*(1+D$28)*(1+$A31)=0,1,'P&L 12T'!$B$12*(1+D$28)*(1+$A31)),0) -> -0.15979782 | E31: =IFERROR(('P&L 12T'!$B$12*(1+E$28)*(1+$A31)-'P&L 12T'!$B$22*(1+$A31)-'Đầu Vào'!$B$45)/IF('P&L 12T'!$B$12*(1+E$28)*(1+$A31)=0,1,'P&L 12T'!$B$12*(1+E$28)*(1+$A31)),0) -> -0.054361657 | F31: =IFERROR(('P&L 12T'!$B$12*(1+F$28)*(1+$A31)-'P&L 12T'!$B$22*(1+$A31)-'Đầu Vào'!$B$45)/IF('P&L 12T'!$B$12*(1+F$28)*(1+$A31)=0,1,'P&L 12T'!$B$12*(1+F$28)*(1+$A31)),0) -> 0.033501814
A32: 0.15 | B32: =IFERROR(('P&L 12T'!$B$12*(1+B$28)*(1+$A32)-'P&L 12T'!$B$22*(1+$A32)-'Đầu Vào'!$B$45)/IF('P&L 12T'!$B$12*(1+B$28)*(1+$A32)=0,1,'P&L 12T'!$B$12*(1+B$28)*(1+$A32)),0) -> -0.41374079 | C32: =IFERROR(('P&L 12T'!$B$12*(1+C$28)*(1+$A32)-'P&L 12T'!$B$22*(1+$A32)-'Đầu Vào'!$B$45)/IF('P&L 12T'!$B$12*(1+C$28)*(1+$A32)=0,1,'P&L 12T'!$B$12*(1+C$28)*(1+$A32)),0) -> -0.25665848 | D32: =IFERROR(('P&L 12T'!$B$12*(1+D$28)*(1+$A32)-'P&L 12T'!$B$22*(1+$A32)-'Đầu Vào'!$B$45)/IF('P&L 12T'!$B$12*(1+D$28)*(1+$A32)=0,1,'P&L 12T'!$B$12*(1+D$28)*(1+$A32)),0) -> -0.13099263 | E32: =IFERROR(('P&L 12T'!$B$12*(1+E$28)*(1+$A32)-'P&L 12T'!$B$22*(1+$A32)-'Đầu Vào'!$B$45)/IF('P&L 12T'!$B$12*(1+E$28)*(1+$A32)=0,1,'P&L 12T'!$B$12*(1+E$28)*(1+$A32)),0) -> -0.028175118 | F32: =IFERROR(('P&L 12T'!$B$12*(1+F$28)*(1+$A32)-'P&L 12T'!$B$22*(1+$A32)-'Đầu Vào'!$B$45)/IF('P&L 12T'!$B$12*(1+F$28)*(1+$A32)=0,1,'P&L 12T'!$B$12*(1+F$28)*(1+$A32)),0) -> 0.057506142
A33: 0.3 | B33: =IFERROR(('P&L 12T'!$B$12*(1+B$28)*(1+$A33)-'P&L 12T'!$B$22*(1+$A33)-'Đầu Vào'!$B$45)/IF('P&L 12T'!$B$12*(1+B$28)*(1+$A33)=0,1,'P&L 12T'!$B$12*(1+B$28)*(1+$A33)),0) -> -0.38604349 | C33: =IFERROR(('P&L 12T'!$B$12*(1+C$28)*(1+$A33)-'P&L 12T'!$B$22*(1+$A33)-'Đầu Vào'!$B$45)/IF('P&L 12T'!$B$12*(1+C$28)*(1+$A33)=0,1,'P&L 12T'!$B$12*(1+C$28)*(1+$A33)),0) -> -0.23203865 | D33: =IFERROR(('P&L 12T'!$B$12*(1+D$28)*(1+$A33)-'P&L 12T'!$B$22*(1+$A33)-'Đầu Vào'!$B$45)/IF('P&L 12T'!$B$12*(1+D$28)*(1+$A33)=0,1,'P&L 12T'!$B$12*(1+D$28)*(1+$A33)),0) -> -0.10883479 | E33: =IFERROR(('P&L 12T'!$B$12*(1+E$28)*(1+$A33)-'P&L 12T'!$B$22*(1+$A33)-'Đầu Vào'!$B$45)/IF('P&L 12T'!$B$12*(1+E$28)*(1+$A33)=0,1,'P&L 12T'!$B$12*(1+E$28)*(1+$A33)),0) -> -0.0080316262 | F33: =IFERROR(('P&L 12T'!$B$12*(1+F$28)*(1+$A33)-'P&L 12T'!$B$22*(1+$A33)-'Đầu Vào'!$B$45)/IF('P&L 12T'!$B$12*(1+F$28)*(1+$A33)=0,1,'P&L 12T'!$B$12*(1+F$28)*(1+$A33)),0) -> 0.075971009

Sheet Kịch Bản
A1: SO SÁNH 3 KỊCH BẢN
A3: GIẢ ĐỊNH KỊCH BẢN
A4: Thông số | B4: Thận Trọng | C4: Cơ Sở | D4: Lạc Quan
A5: Tốc độ tăng KH/tháng | B5: 0.05 | C5: 0.1 | D5: 0.15
A6: Tỷ lệ churn/tháng | B6: 0.08 | C6: 0.05 | D6: 0.03
A7: Hệ số điều chỉnh giá | B7: 0.85 | C7: 1 | D7: 1.1
A9: KẾ T QUẢ DỰ KIẾ N
A10: Chỉ số | B10: Thận Trọng | C10: Cơ Sở | D10: Lạc Quan
A11: DT tháng 1 (triệu) | B11: ='P&L 12T'!$B$12*B7 -> 273.275 | C11: ='P&L 12T'!$B$12*C7 -> 321.5 | D11: ='P&L 12T'!$B$12*D7 -> 353.65
A12: CP NS tháng 1 | B12: ='P&L 12T'!$B$22 -> 301.875 | C12: ='P&L 12T'!$B$22 -> 301.875 | D12: ='P&L 12T'!$B$22 -> 301.875
A13: CP cố định/tháng | B13: ='Đầu Vào'!$B$45 -> 71 | C13: ='Đầu Vào'!$B$45 -> 71 | D13: ='Đầu Vào'!$B$45 -> 71
A14: EBITDA tháng 1 | B14: =B11-B12-B13 -> -99.6 | C14: =C11-C12-C13 -> -51.375 | D14: =D11-D12-D13 -> -19.225
A16: DT tháng 6 | B16: =B11*(1+B5-B6)^5 -> 234.67054 | C16: =C11*(1+C5-C6)^5 -> 410.32452 | D16: =D11*(1+D5-D6)^5 -> 623.25214
A17: CP NS tháng 6 | B17: =B12*(1+B5-B6)^5 -> 259.23033 | C17: =C12*(1+C5-C6)^5 -> 385.2775 | D17: =D12*(1+D5-D6)^5 -> 532.0069
A18: EBITDA tháng 6 | B18: =B16-B17-B13 -> -95.559793 | C18: =C16-C17-C13 -> -45.952974 | D18: =D16-D17-D13 -> 20.245241
A20: DT tháng 12 | B20: =B11*(1+B5-B6)^11 -> 195.47399 | C20: =C11*(1+C5-C6)^11 -> 549.8741 | D20: =D11*(1+D5-D6)^11 -> 1230.1892
A21: CP NS tháng 12 | B21: =B12*(1+B5-B6)^11 -> 215.93161 | C21: =C12*(1+C5-C6)^11 -> 516.30869 | D21: =D12*(1+D5-D6)^11 -> 1050.0873
A22: EBITDA tháng 12 | B22: =B20-B21-B13 -> -91.45762 | C22: =C20-C21-C13 -> -37.43459 | D22: =D20-D21-D13 -> 109.10193
A24: Tháng hòa vốn | B24: =IF(B14>=0,1,IF(B11-B12<=0,0,IFERROR(ROUNDUP(1+LOG(B13/(B11-B12))/LOG(1+B5-B6),0),0))) -> 0 | C24: =IF(C14>=0,1,IF(C11-C12<=0,0,IFERROR(ROUNDUP(1+LOG(C13/(C11-C12))/LOG(1+C5-C6),0),0))) -> 28 | D24: =IF(D14>=0,1,IF(D11-D12<=0,0,IFERROR(ROUNDUP(1+LOG(D13/(D11-D12))/LOG(1+D5-D6),0),0))) -> 4
A25: Headcount cần T12 | B25: =ROUND('Đầu Vào'!$B$35*(1+B5-B6)^11,0) -> 4 | C25: =ROUND('Đầu Vào'!$B$35*(1+C5-C6)^11,0) -> 9 | D25: =ROUND('Đầu Vào'!$B$35*(1+D5-D6)^11,0) -> 17
